<?xml version="1.0" encoding="utf-8"?>
<!-- =================================================================================== -->
<!-- |    This document was autogenerated by xacro from /home/robot/workspaces/driver_ws/src/scitos-g5/scitos_common/scitos_description/urdf/cs_scitos.xacro | -->
<!-- |    EDITING THIS FILE BY HAND IS NOT RECOMMENDED                                 | -->
<!-- =================================================================================== -->
<robot name="scitosG5" xmlns:body="http://playerstage.sourceforge.net/gazebo/xmlschema/#body" xmlns:controller="http://playerstage.sourceforge.net/gazebo/xmlschema/#controller" xmlns:gazebo="http://playerstage.sourceforge.net/gazebo/xmlschema/#gz" xmlns:geom="http://playerstage.sourceforge.net/gazebo/xmlschema/#geom" xmlns:interface="http://playerstage.sourceforge.net/gazebo/xmlschema/#interface" xmlns:joint="http://playerstage.sourceforge.net/gazebo/xmlschema/#joint" xmlns:model="http://playerstage.sourceforge.net/gazebo/xmlschema/#model" xmlns:physics="http://playerstage.sourceforge.net/gazebo/xmlschema/#physics" xmlns:renderable="http://playerstage.sourceforge.net/gazebo/xmlschema/#renderable" xmlns:rendering="http://playerstage.sourceforge.net/gazebo/xmlschema/#rendering" xmlns:sensor="http://playerstage.sourceforge.net/gazebo/xmlschema/#sensor" xmlns:xi="http://www.w3.org/2001/XInclude">
  <!-- materials -->
  <material name="Red">
    <color rgba="0.8 0.0 0.0 1.0"/>
  </material>
  <material name="Black">
    <color rgba="0.02 0.02 0.02 1.0"/>
  </material>
  <material name="Aluminium">
    <color rgba="0.65 0.65 0.65 1.0"/>
  </material>
  <material name="white">
    <color rgba="1 1 1 1"/>
  </material>
  <material name="black">
    <color rgba="0 0 0 1"/>
  </material>
  <material name="red">
    <color rgba="1 0 0 1"/>
  </material>
  <material name="green">
    <color rgba="0 1 0 1"/>
  </material>
  <material name="blue">
    <color rgba="0 0 1 1"/>
  </material>
  <material name="yellow">
    <color rgba="1 1 0 1"/>
  </material>
  <material name="darkgray">
    <color rgba="0.3 0.3 0.3 1"/>
  </material>
  <material name="gray">
    <color rgba="0.7 0.7 0.7 1"/>
  </material>
  <material name="glass">
    <color rgba="1 1 1 0.2"/>
  </material>
  <!-- base_footprint : a fictional link that is on the floor plane, needed for move_base -->
  <link name="base_footprint">
    <visual>
      <origin rpy="0 0 0" xyz="0 0 0"/>
      <geometry>
        <box size="0 0 0"/>
      </geometry>
      <material name="Red"/>
    </visual>
    <collision>
      <origin rpy="0 0 0" xyz="0 0 0"/>
      <geometry>
        <box size="0 0 0"/>
      </geometry>
    </collision>
  </link>
  <!-- base_prismatic : a fictional link that is on the floor plane, needed for moveit -->
  <link name="base_prismatic">
    <visual>
      <origin rpy="0 0 0" xyz="0 0 0"/>
      <geometry>
        <box size="0 0 0"/>
      </geometry>
      <material name="Red"/>
    </visual>
    <collision>
      <origin rpy="0 0 0" xyz="0 0 0"/>
      <geometry>
        <box size="0 0 0"/>
      </geometry>
    </collision>
  </link>
  <!-- base_revolute : a fictional link that is on the floor plane, needed for moveit -->
  <link name="base_revolute">
    <visual>
      <origin rpy="0 0 0" xyz="0 0 0"/>
      <geometry>
        <box size="0 0 0"/>
      </geometry>
      <material name="Red"/>
    </visual>
    <collision>
      <origin rpy="0 0 0" xyz="0 0 0"/>
      <geometry>
        <box size="0 0 0"/>
      </geometry>
    </collision>
  </link>
  <!-- Base link is the actual robot body -->
  <link name="base_link">
    <visual>
      <origin rpy="0 0 0" xyz="0 0 0"/>
      <geometry>
        <mesh filename="package://scitos_description/meshes/cs_scitos_kinect_fixture.dae"/>
      </geometry>
    </visual>
    <collision>
      <origin rpy="0 0 0" xyz="0 0 0.3"/>
      <geometry>
        <cylinder length="0.6" radius="0.2"/>
      </geometry>
    </collision>
  </link>
  <!-- Base revolute -> Base prismatic -->
  <joint name="base_revolute_joint" type="revolute">
    <origin rpy="0 0 0" xyz="0 0 0.0"/>
    <axis xyz="0 0 1"/>
    <parent link="base_revolute"/>
    <child link="base_prismatic"/>
    <limit effort="300" lower="-10" upper="10" velocity="1.5"/>
  </joint>
  <!-- Base prismatic -> Base footprint -->
  <joint name="base_prismatic_joint" type="prismatic">
    <origin rpy="0 0 0" xyz="0 0 0.0"/>
    <axis xyz="1 0 0"/>
    <parent link="base_prismatic"/>
    <child link="base_footprint"/>
    <limit effort="300" lower="-10" upper="10" velocity="1.5"/>
  </joint>
  <!-- Base footprint -> base_link -->
  <joint name="base_footprint_joint" type="fixed">
    <origin rpy="0 0 0" xyz="0 0 0.021"/>
    <parent link="base_footprint"/>
    <child link="base_link"/>
  </joint>
  <!-- base_link -> base_laser_link -->
  <joint name="base_laser_joint" type="fixed">
    <axis xyz="0 1 0"/>
    <origin rpy="0.0 0.0 0.0" xyz="0.1094 0 0.3848"/>
    <parent link="base_link"/>
    <child link="base_laser_link"/>
  </joint>
  <!-- the laser -->
  <link name="base_laser_link" type="laser">
    <visual>
      <origin rpy="0 0 0" xyz="0 0 -0.09"/>
      <geometry>
        <cylinder length="0.18" radius="0.04"/>
      </geometry>
      <material name="yellow"/>
    </visual>
    <collision>
      <origin rpy="0 0 0" xyz="0 0 -0.09"/>
      <geometry>
        <cylinder length="0.18" radius="0.04"/>
      </geometry>
      <material name="yellow"/>
    </collision>
  </link>
  <!-- base_link -> base_kinect_link -->
  <joint name="base_kinect_joint" type="fixed">
    <axis xyz="0 1 0"/>
    <origin rpy="0.0 0.0 0.0" xyz="0.025 0.02 1.18"/>
    <parent link="base_link"/>
    <child link="base_kinect_link"/>
  </joint>
  <!-- the kinect -->
  <link name="base_kinect_link" type="camera">
    <visual>
      <origin rpy="0 0 -1.5707963267948966" xyz=" 0 0 0 "/>
      <geometry>
        <mesh filename="package://scitos_description/meshes/kinect2.dae" scale="0.001 0.001 0.001"/>
      </geometry>
      <origin rpy="0 0 0" xyz="0.0 0.0 0.0"/>
      <geometry>
        <box size="0.0730 0.2760 0.0720"/>
      </geometry>
    </visual>
    <collision>
      <origin rpy="0 0 0" xyz="0.0 0.0 0.0"/>
      <geometry>
        <box size="0.0730 0.2760 0.0720"/>
      </geometry>
    </collision>
  </link>
  <!-- Collision Model Torso  -->
  <joint name="base_link_to_torse_mid" type="fixed">
    <parent link="base_link"/>
    <child link="torso_mid"/>
    <origin xyz="-0.085 0.0 0.8781"/>
  </joint>
  <link name="torso_mid">
    <collision>
      <origin rpy="0 0 0" xyz="0 0 0.0"/>
      <geometry>
        <box size="0.081 0.081 0.620"/>
      </geometry>
    </collision>
    <!--    <visual>
      <origin rpy="0 0 0" xyz="0 0 0.0"/>
      <geometry>
\t\t<box size="0.081 0.081 0.620"/>
      </geometry>
<material name="yellow" />
    </visual>-->
  </link>
  <!-- Collision Model Monitor  -->
  <joint name="base_link_to_monitor" type="fixed">
    <parent link="base_link"/>
    <child link="monitor"/>
    <origin xyz="-0.32 0.0 0.92"/>
  </joint>
  <link name="monitor">
    <!-- <visual>
      <origin rpy="0 0 0" xyz="0 0 0.0"/>
      <geometry>
\t\t<box size="0.32 0.35 0.3"/>
        <material name="yellow" />
    </geometry>
      </visual> -->
    <collision>
      <origin rpy="0 0 0" xyz="0 0 0.0"/>
      <geometry>
        <box size="0.31 0.35 0.4"/>
      </geometry>
    </collision>
  </link>
  <!-- Collision Model torso plate -->
  <joint name="base_link_to_torso_plate" type="fixed">
    <parent link="base_link"/>
    <child link="torso_plate"/>
    <origin xyz="-0.085 0.0 0.5681"/>
  </joint>
  <link name="torso_plate">
    <!--<visual>
      <origin rpy="0 0 0" xyz="0 0 -0.005"/>
      <geometry>
\t\t<cylinder length="0.01" radius="0.195"/>
        <material name="yellow" />
    </geometry>
      </visual>-->
    <collision>
      <origin rpy="0 0 0" xyz="0 0 -0.005"/>
      <geometry>
        <cylinder length="0.01" radius="0.195"/>
      </geometry>
    </collision>
  </link>
  <!-- Collision Model pc_box -->
  <joint name="base_link_to_pc_box" type="fixed">
    <parent link="base_link"/>
    <child link="pc_box"/>
    <origin xyz="-0.085 0.0 0.5581"/>
  </joint>
  <link name="pc_box">
    <!--<visual>
      <origin rpy="0 0 0" xyz="0 0 -0.159"/>
      <geometry>
\t\t<box size="0.276 0.276 0.308"/>
        <material name="yellow" />
    </geometry>
      </visual>-->
    <collision>
      <origin rpy="0 0 0" xyz="0 0 -0.159"/>
      <geometry>
        <box size="0.276 0.276 0.318"/>
      </geometry>
    </collision>
  </link>
  <!-- Collision Model jaco_fixture -->
  <joint name="base_link_to_jaco_fixture" type="fixed">
    <parent link="base_link"/>
    <child link="jaco_fixture"/>
    <origin xyz="-0.085 -0.225 0.85345"/>
  </joint>
  <link name="jaco_fixture">
    <!--<visual>
      <origin rpy="0 0 0" xyz="0 0.065 -0.067"/>
      <geometry>
\t\t<box size="0.08 0.23 0.085"/>
        <material name="yellow" />
    </geometry>
      </visual>-->
    <collision>
      <origin rpy="0 0 0" xyz="0 0.065 -0.067"/>
      <geometry>
        <box size="0.08 0.23 0.085"/>
      </geometry>
    </collision>
  </link>
  <!-- Collision Model kinect_fixture -->
  <joint name="base_link_to_kinect_fixture" type="fixed">
    <parent link="base_link"/>
    <child link="kinect_fixture"/>
    <origin xyz="0.025 0.02 1.18"/>
  </joint>
  <link name="kinect_fixture">
    <!--<visual>
      <origin rpy="0 0 0" xyz="-0.04 0 -0.075"/>
      <geometry>
\t\t<box size="0.055 0.035 0.047"/>
        <material name="yellow" />
    </geometry>
      </visual>-->
    <collision>
      <origin rpy="0 0 0" xyz="-0.04 0 -0.075"/>
      <geometry>
        <box size="0.055 0.035 0.045"/>
      </geometry>
    </collision>
  </link>
  <!-- HEAD -->
  <link name="head_base_frame">
    <visual>
      <geometry>
        <sphere radius="0.15"/>
      </geometry>
      <material name="glass"/>
    </visual>
    <collision>
      <geometry>
        <sphere radius="0.17"/>
      </geometry>
    </collision>
  </link>
  <joint name="base_link_to_head" type="fixed">
    <parent link="base_link"/>
    <child link="head_base_frame"/>
    <origin xyz="-0.075 0 1.32"/>
  </joint>
  <link name="head_swivel_frame">
    <visual>
      <geometry>
        <cylinder length="0.1" radius="0.05"/>
      </geometry>
      <material name="gray"/>
    </visual>
  </link>
  <joint name="HeadPan" type="revolute">
    <parent link="head_base_frame"/>
    <child link="head_swivel_frame"/>
    <axis xyz="0 0 1"/>
    <limit effort="30" lower="-4.537856055185257" upper="1.3962634015954636" velocity="10"/>
  </joint>
  <link name="head_frame">
    <visual>
      <geometry>
        <box size="0.175 0.19 0.07"/>
      </geometry>
      <origin rpy="0 0 0" xyz="0 0 0.02"/>
      <material name="gray"/>
    </visual>
  </link>
  <joint name="HeadTilt" type="revolute">
    <parent link="head_swivel_frame"/>
    <child link="head_frame"/>
    <axis xyz="0 1 0"/>
    <limit effort="30" lower="-0.17453292519943295" upper="0.17453292519943295" velocity="10"/>
  </joint>
  <link name="left_eye_frame">
    <visual>
      <geometry>
        <sphere radius="0.025"/>
      </geometry>
      <material name="white"/>
    </visual>
  </link>
  <joint name="HeadToLeftEyeBase" type="fixed">
    <parent link="head_frame"/>
    <child link="left_eye_base_frame"/>
    <origin xyz="0.08 0.05 0.02"/>
  </joint>
  <joint name="EyesTilt" type="revolute">
    <parent link="left_eye_base_frame"/>
    <child link="left_eye_swivel_frame"/>
    <axis xyz="0 1 0"/>
    <limit effort="30" lower="-3.1415926535897931" upper="3.1415926535897931" velocity="10"/>
  </joint>
  <joint name="EyesPan" type="revolute">
    <parent link="left_eye_swivel_frame"/>
    <child link="left_eye_frame"/>
    <axis xyz="0 0 1"/>
    <limit effort="30" lower="-3.1415926535897931" upper="3.1415926535897931" velocity="10"/>
  </joint>
  <link name="right_eye_frame">
    <visual>
      <geometry>
        <sphere radius="0.025"/>
      </geometry>
      <material name="white"/>
    </visual>
  </link>
  <joint name="head_to_right_eye_base" type="fixed">
    <parent link="head_frame"/>
    <child link="right_eye_base_frame"/>
    <origin xyz="0.08 -0.05 0.02"/>
  </joint>
  <joint name="RightEyeBaseToRightEyeSwivel" type="revolute">
    <parent link="right_eye_base_frame"/>
    <child link="right_eye_swivel_frame"/>
    <axis xyz="0 1 0"/>
    <limit effort="30" lower="-3.1415926535897931" upper="3.1415926535897931" velocity="10"/>
    <mimic joint="EyesTilt"/>
  </joint>
  <joint name="RightEyeSwivelToRightEye" type="revolute">
    <parent link="right_eye_swivel_frame"/>
    <child link="right_eye_frame"/>
    <axis xyz="0 0 1"/>
    <limit effort="30" lower="-3.1415926535897931" upper="3.1415926535897931" velocity="10"/>
    <mimic joint="EyesPan"/>
  </joint>
  <link name="right_eye_base_frame"/>
  <link name="left_eye_base_frame"/>
  <link name="right_eye_swivel_frame"/>
  <link name="left_eye_swivel_frame"/>
</robot>

